Workbook
Name Slicer_Capai_Target1: #N/A
Name Slicer_Employee_Name: #N/A
Name Slicer_ID_Account: #N/A
Name Slicer_Kategori: #N/A
Name Slicer_Nama_Employee: #N/A
Name Slicer_Rajin_Ngga1: #N/A

Sheet Dashboard Karyawan
A1: DASHBOARD KARYAWAN BHINNEKA GROUP

Sheet Dashboard Penjualan
A1: DASHBOARD PENJUALAN BHINNEKA GROUP

Sheet Pivot Karyawan
A3: Count of Employee ID | B3: Average of Attendance Rate | C3: Average of Capai Target | D3: Sum of Insentif
A4: 10 | B4: 0.884 | C4: 0.4 | D4: 14000000
A7: Row Labels | B7: Average of Attendance Rate | C7: dibawah | D7: diantara | E7: diatas | G7: Row Labels | H7: Sum of Achievement Sales | J7: Row Labels | K7: Sum of Insentif | M7: Row Labels | N7: Sum of Total Penjualan
A8: E001 | B8: 0.95 | C8: =IF(B8<85%,B8,NA()) -> #N/A | D8: =IF(AND(B8>=85%,B8<=95%),B8,NA()) -> 0.95 | E8: =IF(B8>95%,B8,NA()) -> #N/A | G8: Andi Pratama | H8: 1.2490944 | J8: Rajin | K8: 14000000 | M8: Citra Dewi | N8: 4.6574459e+08
A9: E002 | B9: 0.85 | C9: =IF(B9<85%,B9,NA()) -> #N/A | D9: =IF(AND(B9>=85%,B9<=95%),B9,NA()) -> 0.85 | E9: =IF(B9>95%,B9,NA()) -> #N/A | G9: Budi Santoso | H9: 0.70256295 | J9: Tidak Rajin | K9: 0 | M9: Eko Wijaya | N9: 258361650
A10: E003 | B10: 0.7 | C10: =IF(B10<85%,B10,NA()) -> 0.7 | D10: =IF(AND(B10>=85%,B10<=95%),B10,NA()) -> #N/A | E10: =IF(B10>95%,B10,NA()) -> #N/A | G10: Citra Dewi | H10: 1.2365831 | J10: Grand Total | K10: 14000000 | M10: Hadi Nugroho | N10: 206804000
A11: E004 | B11: 0.98 | C11: =IF(B11<85%,B11,NA()) -> #N/A | D11: =IF(AND(B11>=85%,B11<=95%),B11,NA()) -> #N/A | E11: =IF(B11>95%,B11,NA()) -> 0.98 | G11: Dewi Lestari | H11: 0.6912522 | M11: Gita Rahma | N11: 155930400
A12: E005 | B12: 0.9 | C12: =IF(B12<85%,B12,NA()) -> #N/A | D12: =IF(AND(B12>=85%,B12<=95%),B12,NA()) -> 0.9 | E12: =IF(B12>95%,B12,NA()) -> #N/A | G12: Eko Wijaya | H12: 0.71528712 | M12: Fani Sari | N12: 118154250
A13: E006 | B13: 0.92 | C13: =IF(B13<85%,B13,NA()) -> #N/A | D13: =IF(AND(B13>=85%,B13<=95%),B13,NA()) -> 0.92 | E13: =IF(B13>95%,B13,NA()) -> #N/A | G13: Fani Sari | H13: 1.1436937 | M13: Joko Susilo | N13: 116284150
A14: E007 | B14: 0.8 | C14: =IF(B14<85%,B14,NA()) -> 0.8 | D14: =IF(AND(B14>=85%,B14<=95%),B14,NA()) -> #N/A | E14: =IF(B14>95%,B14,NA()) -> #N/A | G14: Gita Rahma | H14: 0.9650926 | M14: Indah Putri | N14: 112535750
A15: E008 | B15: 0.88 | C15: =IF(B15<85%,B15,NA()) -> #N/A | D15: =IF(AND(B15>=85%,B15<=95%),B15,NA()) -> 0.88 | E15: =IF(B15>95%,B15,NA()) -> #N/A | G15: Hadi Nugroho | H15: 1.0850341 | M15: Budi Santoso | N15: 77811000
A16: E009 | B16: 0.97 | C16: =IF(B16<85%,B16,NA()) -> #N/A | D16: =IF(AND(B16>=85%,B16<=95%),B16,NA()) -> #N/A | E16: =IF(B16>95%,B16,NA()) -> 0.97 | G16: Indah Putri | H16: 0.81345785 | M16: Dewi Lestari | N16: 69620175
A17: E010 | B17: 0.89 | C17: =IF(B17<85%,B17,NA()) -> #N/A | D17: =IF(AND(B17>=85%,B17<=95%),B17,NA()) -> 0.89 | E17: =IF(B17>95%,B17,NA()) -> #N/A | G17: Joko Susilo | H17: 0.69420822 | M17: Andi Pratama | N17: 12509000
A18: Grand Total | B18: 0.884 | C18: =IF(B18<85%,B18,NA()) -> #N/A | D18: =IF(AND(B18>=85%,B18<=95%),B18,NA()) -> 0.884 | E18: =IF(B18>95%,B18,NA()) -> #N/A | G18: Grand Total | H18: 9.2962662 | M18: Grand Total | N18: 1.593755e+09
A23: Employee | B23: Capai Target | C23: Tidak Capai Target
A24: Andi Pratama | B24: =IF(H8>=100%,H8,NA()) -> 1.2490944 | C24: =IF(H8<100%,H8,NA()) -> #N/A
A25: Budi Santoso | B25: =IF(H9>=100%,H9,NA()) -> #N/A | C25: =IF(H9<100%,H9,NA()) -> 0.70256295
A26: Citra Dewi | B26: =IF(H10>=100%,H10,NA()) -> 1.2365831 | C26: =IF(H10<100%,H10,NA()) -> #N/A
A27: Dewi Lestari | B27: =IF(H11>=100%,H11,NA()) -> #N/A | C27: =IF(H11<100%,H11,NA()) -> 0.6912522
A28: Eko Wijaya | B28: =IF(H12>=100%,H12,NA()) -> #N/A | C28: =IF(H12<100%,H12,NA()) -> 0.71528712
A29: Fani Sari | B29: =IF(H13>=100%,H13,NA()) -> 1.1436937 | C29: =IF(H13<100%,H13,NA()) -> #N/A
A30: Gita Rahma | B30: =IF(H14>=100%,H14,NA()) -> #N/A | C30: =IF(H14<100%,H14,NA()) -> 0.9650926
A31: Hadi Nugroho | B31: =IF(H15>=100%,H15,NA()) -> 1.0850341 | C31: =IF(H15<100%,H15,NA()) -> #N/A
A32: Indah Putri | B32: =IF(H16>=100%,H16,NA()) -> #N/A | C32: =IF(H16<100%,H16,NA()) -> 0.81345785
A33: Joko Susilo | B33: =IF(H17>=100%,H17,NA()) -> #N/A | C33: =IF(H17<100%,H17,NA()) -> 0.69420822

Sheet Pivot Penjualan
A1: Total Revenue | B1: Total Quantity | C1: Jumlah Transaksi | D1: Rata-rata harga per unit
A3: Count of ID Transaksi | B3: Sum of Total transaksi | C3: Sum of Kuantitas | D3: Average of Harga Produk
A4: 8680 | B4: 1.593755e+09 | C4: 18645 | D4: 102915.2
A7: Row Labels | B7: Sum of Penjualan dalam Juta Rupiah | D7: Row Labels | E7: Sum of Total transaksi | G7: Row Labels | H7: Sum of Total transaksi | J7: Row Labels | K7: Sum of Total transaksi
A8: Jan | B8: 177.45607 | D8: 0 | E8: 695300 | G8: BHINNEKA Gaming Keyboard MAXFIT 67 MK-858 White WHITE SWITCH | H8: 16332000 | J8: O-14 | K8: 4.1318669e+08
A9: Feb | B9: 30.317786 | D9: GAMING COMBO | E9: 4602400 | G9: BHINNEKA MAXFIT70 70% MECHANICAL KEYBOARD LONDON TOUR (WHITE BLUE) BROWN SWITCH | H9: 16947000 | J9: O-07 | K9: 258361650
A10: Mar | B10: 35.246829 | D10: BASIC MOUSEPAD | E10: 8437350 | G10: BHINNEKA POWER PLUS 65W 3-PORTS GAN CHARGER (PPS/PD+QC) BLACK | H10: 17473750 | J10: O-10 | K10: 206804000
A11: Apr | B11: 12.95285 | D11: DESK | E11: 12073600 | G11: BHINNEKA ARIA XD7 GAMING MOUSE ZORO | H11: 18879000 | J11: O-08 | K11: 118154250
A12: May | B12: 39.918845 | D12: CN COOLER/ PC FAN ACC/ STAND LAPTOP | E12: 13086400 | G12: BHINNEKA POWER CUBE 4 PLUG TYPE TRAVEL MULTI ADAPTER BLACK | H12: 19857900 | J12: O-13 | K12: 112535750
A13: Jun | B13: 254.08477 | D13: OFFICE COMBO | E13: 18277050 | G13: BHINNEKA MAXFIT70 70% MECHANICAL KEYBOARD EPIC GREYSCALE (WHITE GRAY) YELLOW SWITCH | H13: 22776600 | J13: O-15 | K13: 80251550
A14: Jul | B14: 320.70021 | D14: OFFICE CHAIR | E14: 22803900 | G14: BHINNEKA MAXFIT70 70% MECHANICAL KEYBOARD EPIC GREYSCALE (WHITE GRAY) BROWN SWITCH | H14: 24479000 | J14: O-03 | K14: 77811000
A15: Aug | B15: 148.6894 | D15: GAMING MOUSEPAD | E15: 29552050 | G15: BHINNEKA ATO MP905 DESKMAT ONE PIECE LUFFY | H15: 28642600 | J15: O-11 | K15: 63403900
A16: Sep | B16: 107.87616 | D16: STREAMING DEVICES | E16: 33728700 | G16: BHINNEKA ARIA XD7 GAMING MOUSE LUFFY | H16: 32094300 | J16: O-09 | K16: 62280200
A17: Oct | B17: 49.996829 | D17: CAR & TRAVEL CHARGER | E17: 34440300 | G17: BHINNEKA ATO MP905 DESKMAT ONE PIECE ZORO | H17: 32834200 | J17: O-05 | K17: 60132425
A18: Nov | B18: 308.86323 | D18: EARPHONE | E18: 43158125 | G18: Grand Total | H18: 230316350 | J18: O-04 | K18: 52557900
A19: Dec | B19: 107.65199 | D19: OTHER ACCESSORIES | E19: 44373288 | J19: O-16 | K19: 36032600
A20: Grand Total | B20: 1593.755 | D20: POWERBANK | E20: 49550350 | J20: O-12 | K20: 30246300
D21: SMART LIFE | E21: 54533300 | J21: O-06 | K21: 9487750
D22: GAMEPAD | E22: 60647600 | J22: O-01 | K22: 7494900
D23: WIRELESS HEADSET | E23: 68507650 | J23: O-02 | K23: 5014100
D24: OFFICE MOUSE | E24: 76576650 | J24: Grand Total | K24: 1.593755e+09
D25: GAMING HEADSET | E25: 83096300
D26: TWS | E26: 94325450
D27: DESKMAT | E27: 114355500
D28: CHARGER | E28: 151693300
D29: CABLE | E29: 1.665094e+08
D30: KEYBOARD GAMING | E30: 200095000
D31: MOUSE GAMING | E31: 208636000
D32: Grand Total | E32: 1.593755e+09

Sheet Data Penjualan
A1: ID Transaksi | B1: ID Account | C1: Tanggal | D1: ID Outlet | E1: ID Produk | F1: Kuantitas | G1: Harga Produk | H1: Total transaksi | I1: Nama Barang | J1: Kategori Barang | K1: PIC | L1: Nama Outlet
A2: ="T-0"&ROW()-1 -> T-01 | B2: AC-1 | C2: 45656 | D2: O-13 | E2: P-1955 | F2: 1 | G2: =VLOOKUP(E2,'Data Produk'!$A$2:$E$2517,5,FALSE) -> 17100 | H2: =G2*F2 -> 17100 | I2: =VLOOKUP(E2,'Data Produk'!$A$2:$E$2517,3,FALSE) -> KC103 BHINNEKA USB CABLE TYPE C | J2: =VLOOKUP(E2,'Data Produk'!$A$2:$E$2517,4,FALSE) -> CABLE | K2: =VLOOKUP(D2,'Data Outlet'!$A$2:$D$17,4,FALSE) -> Indah Putri | L2: =VLOOKUP(D2,'Data Outlet'!$A$2:$D$17,2,FALSE) -> PIK AVENUE
A3: ="T-0"&ROW()-1 -> T-02 | B3: AC-1 | C3: 45639 | D3: O-10 | E3: P-1401 | F3: 1 | G3: =VLOOKUP(E3,'Data Produk'!$A$2:$E$2517,5,FALSE) -> 123300 | H3: =G3*F3 -> 123300 | I3: =VLOOKUP(E3,'Data Produk'!$A$2:$E$2517,3,FALSE) -> BHINNEKA GO WK894 OFFICE COMBO BLACK | J3: =VLOOKUP(E3,'Data Produk'!$A$2:$E$2517,4,FALSE) -> OFFICE COMBO | K3: =VLOOKUP(D3,'Data Outlet'!$A$2:$D$17,4,FALSE) -> Hadi Nugroho | L3: =VLOOKUP(D3,'Data Outlet'!$A$2:$D$17,2,FALSE) -> MALL KELAPA GADING
A4: ="T-0"&ROW()-1 -> T-03 | B4: AC-1 | C4: 45628 | D4: O-16 | E4: P-2396 | F4: 5 | G4: =VLOOKUP(E4,'Data Produk'!$A$2:$E$2517,5,FALSE) -> 18000 | H4: =G4*F4 -> 90000 | I4: =VLOOKUP(E4,'Data Produk'!$A$2:$E$2517,3,FALSE) -> BHINNEKA DURALINK KLB1201 BLACK | J4: =VLOOKUP(E4,'Data Produk'!$A$2:$E$2517,4,FALSE) -> CABLE | K4: =VLOOKUP(D4,'Data Outlet'!$A$2:$D$17,4,FALSE) -> Joko Susilo | L4: =VLOOKUP(D4,'Data Outlet'!$A$2:$D$17,2,FALSE) -> SUMARECON MALL SERPONG
A5: ="T-0"&ROW()-1 -> T-04 | B5: AC-1 | C5: 45634 | D5: O-10 | E5: P-1441 | F5: 3 | G5: =VLOOKUP(E5,'Data Produk'!$A$2:$E$2517,5,FALSE) -> 243000 | H5: =G5*F5 -> 729000 | I5: =VLOOKUP(E5,'Data Produk'!$A$2:$E$2517,3,FALSE) -> BHINNEKA POWER PLUS 65W 3-PORTS GAN CHARGER (PPS/PD+QC) BLACK | J5: =VLOOKUP(E5,'Data Produk'!$A$2:$E$2517,4,FALSE) -> CHARGER | K5: =VLOOKUP(D5,'Data Outlet'!$A$2:$D$17,4,FALSE) -> Hadi Nugroho | L5: =VLOOKUP(D5,'Data Outlet'!$A$2:$D$17,2,FALSE) -> MALL KELAPA GADING
A6: ="T-0"&ROW()-1 -> T-05 | B6: AC-1 | C6: 45630 | D6: O-13 | E6: P-1854 | F6: 1 | G6: =VLOOKUP(E6,'Data Produk'!$A$2:$E$2517,5,FALSE) -> 57600 | H6: =G6*F6 -> 57600 | I6: =VLOOKUP(E6,'Data Produk'!$A$2:$E$2517,3,FALSE) -> BHINNEKA GO W192 OFFICE MOUSE BLACK | J6: =VLOOKUP(E6,'Data Produk'!$A$2:$E$2517,4,FALSE) -> OFFICE MOUSE | K6: =VLOOKUP(D6,'Data Outlet'!$A$2:$D$17,4,FALSE) -> Indah Putri | L6: =VLOOKUP(D6,'Data Outlet'!$A$2:$D$17,2,FALSE) -> PIK AVENUE
A7: ="T-0"&ROW()-1 -> T-06 | B7: AC-1 | C7: 45645 | D7: O-13 | E7: P-1914 | F7: 3 | G7: =VLOOKUP(E7,'Data Produk'!$A$2:$E$2517,5,FALSE) -> 90000 | H7: =G7*F7 -> 270000 | I7: =VLOOKUP(E7,'Data Produk'!$A$2:$E$2517,3,FALSE) -> BHINNEKA POWER PURE 33W 2-PORTS USB CHARGER (PD+QC) BLACK | J7: =VLOOKUP(E7,'Data Produk'!$A$2:$E$2517,4,FALSE) -> CHARGER | K7: =VLOOKUP(D7,'Data Outlet'!$A$2:$D$17,4,FALSE) -> Indah Putri | L7: =VLOOKUP(D7,'Data Outlet'!$A$2:$D$17,2,FALSE) -> PIK AVENUE
A8: ="T-0"&ROW()-1 -> T-07 | B8: AC-1 | C8: 45644 | D8: O-10 | E8: P-1312 | F8: 3 | G8: =VLOOKUP(E8,'Data Produk'!$A$2:$E$2517,5,FALSE) -> 27000 | H8: =G8*F8 -> 81000 | I8: =VLOOKUP(E8,'Data Produk'!$A$2:$E$2517,3,FALSE) -> BHINNEKA DURALINK KCB2001 BLACK | J8: =VLOOKUP(E8,'Data Produk'!$A$2:$E$2517,4,FALSE) -> CABLE | K8: =VLOOKUP(D8,'Data Outlet'!$A$2:$D$17,4,FALSE) -> Hadi Nugroho | L8: =VLOOKUP(D8,'Data Outlet'!$A$2:$D$17,2,FALSE) -> MALL KELAPA GADING
A9: ="T-0"&ROW()-1 -> T-08 | B9: AC-1 | C9: 45650 | D9: O-10 | E9: P-1416 | F9: 3 | G9: =VLOOKUP(E9,'Data Produk'!$A$2:$E$2517,5,FALSE) -> 15300 | H9: =G9*F9 -> 45900 | I9: =VLOOKUP(E9,'Data Produk'!$A$2:$E$2517,3,FALSE) -> BHINNEKA LINKPODS ES3 WIRED EARBUDS BLACK | J9: =VLOOKUP(E9,'Data Produk'!$A$2:$E$2517,4,FALSE) -> EARPHONE | K9: =VLOOKUP(D9,'Data Outlet'!$A$2:$D$17,4,FALSE) -> Hadi Nugroho | L9: =VLOOKUP(D9,'Data Outlet'!$A$2:$D$17,2,FALSE) -> MALL KELAPA GADING
A10: ="T-0"&ROW()-1 -> T-09 | B10: AC-1 | C10: 45656 | D10: O-04 | E10: P-357 | F10: 1 | G10: =VLOOKUP(E10,'Data Produk'!$A$2:$E$2517,5,FALSE) -> 162000 | H10: =G10*F10 -> 162000 | I10: =VLOOKUP(E10,'Data Produk'!$A$2:$E$2517,3,FALSE) -> BHINNEKA POWER PACK T1 10.000 mAh 22,5W POWERBANK BLACK | J10: =VLOOKUP(E10,'Data Produk'!$A$2:$E$2517,4,FALSE) -> POWERBANK | K10: =VLOOKUP(D10,'Data Outlet'!$A$2:$D$17,4,FALSE) -> Citra Dewi | L10: =VLOOKUP(D10,'Data Outlet'!$A$2:$D$17,2,FALSE) -> CENTER POINT MEDAN
A11: ="T-"&ROW()-1 -> T-10 | B11: AC-1 | C11: 45633 | D11: O-10 | E11: P-1421 | F11: 1 | G11: =VLOOKUP(E11,'Data Produk'!$A$2:$E$2517,5,FALSE) -> 40500 | H11: =G11*F11 -> 40500 | I11: =VLOOKUP(E11,'Data Produk'!$A$2:$E$2517,3,FALSE) -> BHINNEKA MEOW AC5001 HEADSET ACCESSORIES WHITE | J11: =VLOOKUP(E11,'Data Produk'!$A$2:$E$2517,4,FALSE) -> OTHER ACCESSORIES | K11: =VLOOKUP(D11,'Data Outlet'!$A$2:$D$17,4,FALSE) -> Hadi Nugroho | L11: =VLOOKUP(D11,'Data Outlet'!$A$2:$D$17,2,FALSE) -> MALL KELAPA GADING
A12: ="T-"&ROW()-1 -> T-11 | B12: AC-1 | C12: 45629 | D12: O-10 | E12: P-1378 | F12: 2 | G12: =VLOOKUP(E12,'Data Produk'!$A$2:$E$2517,5,FALSE) -> 189000 | H12: =G12*F12 -> 378000 | I12: =VLOOKUP(E12,'Data Produk'!$A$2:$E$2517,3,FALSE) -> BHINNEKA GO TUNE WH06 WIRELESS HEADSET BEIGE | J12: =VLOOKUP(E12,'Data Produk'!$A$2:$E$2517,4,FALSE) -> WIRELESS HEADSET | K12: =VLOOKUP(D12,'Data Outlet'!$A$2:$D$17,4,FALSE) -> Hadi Nugroho | L12: =VLOOKUP(D12,'Data Outlet'!$A$2:$D$17,2,FALSE) -> MALL KELAPA GADING
A13: ="T-"&ROW()-1 -> T-12 | B13: AC-1 | C13: 45642 | D13: O-16 | E13: P-2462 | F13: 2 | G13: =VLOOKUP(E13,'Data Produk'!$A$2:$E$2517,5,FALSE) -> 98100 | H13: =G13*F13 -> 196200 | I13: =VLOOKUP(E13,'Data Produk'!$A$2:$E$2517,3,FALSE) -> BHINNEKA POWER PURE 30W 2-PORTS USB CHARGER (PD+QC) WHITE | J13: =VLOOKUP(E13,'Data Produk'!$A$2:$E$2517,4,FALSE) -> CHARGER | K13: =VLOOKUP(D13,'Data Outlet'!$A$2:$D$17,4,FALSE) -> Joko Susilo | L13: =VLOOKUP(D13,'Data Outlet'!$A$2:$D$17,2,FALSE) -> SUMARECON MALL SERPONG
A14: ="T-"&ROW()-1 -> T-13 | B14: AC-1 | C14: 45638 | D14: O-04 | E14: P-265 | F14: 1 | G14: =VLOOKUP(E14,'Data Produk'!$A$2:$E$2517,5,FALSE) -> 202500 | H14: =G14*F14 -> 202500 | I14: =VLOOKUP(E14,'Data Produk'!$A$2:$E$2517,3,FALSE) -> BHINNEKA ATOM FULL SIZE MECHANICAL KEYBOARD GREY BLUE SWITCH | J14: =VLOOKUP(E14,'Data Produk'!$A$2:$E$2517,4,FALSE) -> KEYBOARD GAMING | K14: =VLOOKUP(D14,'Data Outlet'!$A$2:$D$17,4,FALSE) -> Citra Dewi | L14: =VLOOKUP(D14,'Data Outlet'!$A$2:$D$17,2,FALSE) -> CENTER POINT MEDAN
A15: ="T-"&ROW()-1 -> T-14 | B15: AC-1 | C15: 45628 | D15: O-16 | E15: P-2508 | F15: 3 | G15: =VLOOKUP(E15,'Data Produk'!$A$2:$E$2517,5,FALSE) -> 32000 | H15: =G15*F15 -> 96000 | I15: =VLOOKUP(E15,'Data Produk'!$A$2:$E$2517,3,FALSE) -> KL104 BHINNEKA USB CABLE LIGHTNING | J15: =VLOOKUP(E15,'Data Produk'!$A$2:$E$2517,4,FALSE) -> CABLE | K15: =VLOOKUP(D15,'Data Outlet'!$A$2:$D$17,4,FALSE) -> Joko Susilo | L15: =VLOOKUP(D15,'Data Outlet'!$A$2:$D$17,2,FALSE) -> SUMARECON MALL SERPONG
A16: ="T-"&ROW()-1 -> T-15 | B16: AC-1 | C16: 45638 | D16: O-16 | E16: P-2430 | F16: 1 | G16: =VLOOKUP(E16,'Data Produk'!$A$2:$E$2517,5,FALSE) -> 39600 | H16: =G16*F16 -> 39600 | I16: =VLOOKUP(E16,'Data Produk'!$A$2:$E$2517,3,FALSE) -> BHINNEKA GO W607 OFFICE MOUSE PURPLE | J16: =VLOOKUP(E16,'Data Produk'!$A$2:$E$2517,4,FALSE) -> OFFICE MOUSE | K16: =VLOOKUP(D16,'Data Outlet'!$A$2:$D$17,4,FALSE) -> Joko Susilo | L16: =VLOOKUP(D16,'Data Outlet'!$A$2:$D$17,2,FALSE) -> SUMARECON MALL SERPONG
A17: ="T-"&ROW()-1 -> T-16 | B17: AC-1 | C17: 45633 | D17: O-10 | E17: P-1375 | F17: 1 | G17: =VLOOKUP(E17,'Data Produk'!$A$2:$E$2517,5,FALSE) -> 26100 | H17: =G17*F17 -> 26100 | I17: =VLOOKUP(E17,'Data Produk'!$A$2:$E$2517,3,FALSE) -> BHINNEKA GO ES1 WIRED EARBUDS WHITE | J17: =VLOOKUP(E17,'Data Produk'!$A$2:$E$2517,4,FALSE) -> EARPHONE | K17: =VLOOKUP(D17,'Data Outlet'!$A$2:$D$17,4,FALSE) -> Hadi Nugroho | L17: =VLOOKUP(D17,'Data Outlet'!$A$2:$D$17,2,FALSE) -> MALL KELAPA GADING
A18: ="T-"&ROW()-1 -> T-17 | B18: AC-1 | C18: 45631 | D18: O-10 | E18: P-1431 | F18: 1 | G18: =VLOOKUP(E18,'Data Produk'!$A$2:$E$2517,5,FALSE) -> 49500 | H18: =G18*F18 -> 49500 | I18: =VLOOKUP(E18,'Data Produk'!$A$2:$E$2517,3,FALSE) -> BHINNEKA POWER GO 20W 1-PORT TYPE-C USB CHARGER (PD+QC) BLACK | J18: =VLOOKUP(E18,'Data Produk'!$A$2:$E$2517,4,FALSE) -> CHARGER | K18: =VLOOKUP(D18,'Data Outlet'!$A$2:$D$17,4,FALSE) -> Hadi Nugroho | L18: =VLOOKUP(D18,'Data Outlet'!$A$2:$D$17,2,FALSE) -> MALL KELAPA GADING
A19: ="T-"&ROW()-1 -> T-18 | B19: AC-1 | C19: 45646 | D19: O-10 | E19: P-1407 | F19: 5 | G19: =VLOOKUP(E19,'Data Produk'!$A$2:$E$2517,5,FALSE) -> 31500 | H19: =G19*F19 -> 157500 | I19: =VLOOKUP(E19,'Data Produk'!$A$2:$E$2517,3,FALSE) -> BHINNEKA HYPERLINK KD60L1501 BLACK | J19: =VLOOKUP(E19,'Data Produk'!$A$2:$E$2517,4,FALSE) -> CABLE | K19: =VLOOKUP(D19,'Data Outlet'!$A$2:$D$17,4,FALSE) -> Hadi Nugroho | L19: =VLOOKUP(D19,'Data Outlet'!$A$2:$D$17,2,FALSE) -> MALL KELAPA GADING
A20: ="T-"&ROW()-1 -> T-19 | B20: AC-1 | C20: 45652 | D20: O-10 | E20: P-1445 | F20: 5 | G20: =VLOOKUP(E20,'Data Produk'!$A$2:$E$2517,5,FALSE) -> 89100 | H20: =G20*F20 -> 445500 | I20: =VLOOKUP(E20,'Data Produk'!$A$2:$E$2517,3,FALSE) -> BHINNEKA POWER PURE 33W 2-PORTS USB CHARGER (PD+QC) BLACK | J20: =VLOOKUP(E20,'Data Produk'!$A$2:$E$2517,4,FALSE) -> CHARGER | K20: =VLOOKUP(D20,'Data Outlet'!$A$2:$D$17,4,FALSE) -> Hadi Nugroho | L20: =VLOOKUP(D20,'Data Outlet'!$A$2:$D$17,2,FALSE) -> MALL KELAPA GADING
A21: ="T-"&ROW()-1 -> T-20 | B21: AC-1 | C21: 45627 | D21: O-10 | E21: P-1299 | F21: 2 | G21: =VLOOKUP(E21,'Data Produk'!$A$2:$E$2517,5,FALSE) -> 12600 | H21: =G21*F21 -> 25200 | I21: =VLOOKUP(E21,'Data Produk'!$A$2:$E$2517,3,FALSE) -> BHINNEKA BASIC XL MP64 BASIC MOUSEPAD BLACK | J21: =VLOOKUP(E21,'Data Produk'!$A$2:$E$2517,4,FALSE) -> BASIC MOUSEPAD | K21: =VLOOKUP(D21,'Data Outlet'!$A$2:$D$17,4,FALSE) -> Hadi Nugroho | L21: =VLOOKUP(D21,'Data Outlet'!$A$2:$D$17,2,FALSE) -> MALL KELAPA GADING
A22: ="T-"&ROW()-1 -> T-21 | B22: AC-1 | C22: 45635 | D22: O-05 | E22: P-464 | F22: 1 | G22: =VLOOKUP(E22,'Data Produk'!$A$2:$E$2517,5,FALSE) -> 89100 | H22: =G22*F22 -> 89100 | I22: =VLOOKUP(E22,'Data Produk'!$A$2:$E$2517,3,FALSE) -> BHINNEKA Gaming Headset Stand Tower AC3004 MINT | J22: =VLOOKUP(E22,'Data Produk'!$A$2:$E$2517,4,FALSE) -> OTHER ACCESSORIES | K22: =VLOOKUP(D22,'Data Outlet'!$A$2:$D$17,4,FALSE) -> Dewi Lestari | L22: =VLOOKUP(D22,'Data Outlet'!$A$2:$D$17,2,FALSE) -> CIBUBUR JUNCTION
... A8681: ="T-"&ROW()-1 -> T-8680 | B8681: AC-2 | C8681: 45321 | D8681: O-14 | E8681: P-1978 | F8681: 14 | G8681: =VLOOKUP(E8681,'Data Produk'!$A$2:$E$2517,5,FALSE) -> 629300 | H8681: =G8681*F8681 -> 8810200 | I8681: =VLOOKUP(E8681,'Data Produk'!$A$2:$E$2517,3,FALSE) -> BHINNEKA ARIA XD7 GAMING MOUSE LUFFY | J8681: =VLOOKUP(E8681,'Data Produk'!$A$2:$E$2517,4,FALSE) -> MOUSE GAMING | K8681: =VLOOKUP(D8681,'Data Outlet'!$A$2:$D$17,4,FALSE) -> Citra Dewi | L8681: =VLOOKUP(D8681,'Data Outlet'!$A$2:$D$17,2,FALSE) -> PONDOK INDAH MALL

Sheet Data Employee
A1: Employee ID | B1: Employee Name | C1: Sales Target | D1: Attendance Rate | E1: Rajin/Ngga | F1: Total Penjualan | G1: Achievement Sales | H1: Insentif | I1: Capai Target
A2: E001 | B2: Andi Pratama | C2: 10014455 | D2: 0.95 | E2: =IF(D2>90%,"Rajin","Tidak Rajin") -> Rajin | F2: =SUMIF('Data Penjualan'!K:K,'Data Employee'!B2,'Data Penjualan'!H:H) -> 12509000 | G2: =F2/C2 -> 1.2490944 | H2: =IFERROR(_xlfn.IFS(AND(D2>100%,G2>100%),18000000,AND(D2>95%,G2>95%),10000000,AND(D2>90%,G2>95%),7000000,AND(D2>90%,G2>90%),5000000),0) -> 7000000 | I2: =IF(G2>=100%,"Capai","Tidak Capai Target") -> Capai
A3: E002 | B3: Budi Santoso | C3: 1.1075306e+08 | D3: 0.85 | E3: =IF(D3>90%,"Rajin","Tidak Rajin") -> Tidak Rajin | F3: =SUMIF('Data Penjualan'!K:K,'Data Employee'!B3,'Data Penjualan'!H:H) -> 77811000 | G3: =F3/C3 -> 0.70256295 | H3: =IFERROR(_xlfn.IFS(AND(D3>100%,G3>100%),18000000,AND(D3>95%,G3>95%),10000000,AND(D3>90%,G3>95%),7000000,AND(D3>90%,G3>90%),5000000),0) -> 0 | I3: =IF(G3>=100%,"Capai","Tidak Capai Target") -> Tidak Capai Target
A4: E003 | B4: Citra Dewi | C4: 3.7663833e+08 | D4: 0.7 | E4: =IF(D4>90%,"Rajin","Tidak Rajin") -> Tidak Rajin | F4: =SUMIF('Data Penjualan'!K:K,'Data Employee'!B4,'Data Penjualan'!H:H) -> 4.6574459e+08 | G4: =F4/C4 -> 1.2365831 | H4: =IFERROR(_xlfn.IFS(AND(D4>100%,G4>100%),18000000,AND(D4>95%,G4>95%),10000000,AND(D4>90%,G4>95%),7000000,AND(D4>90%,G4>90%),5000000),0) -> 0 | I4: =IF(G4>=100%,"Capai","Tidak Capai Target") -> Capai
A5: E004 | B5: Dewi Lestari | C5: 1.0071603e+08 | D5: 0.98 | E5: =IF(D5>90%,"Rajin","Tidak Rajin") -> Rajin | F5: =SUMIF('Data Penjualan'!K:K,'Data Employee'!B5,'Data Penjualan'!H:H) -> 69620175 | G5: =F5/C5 -> 0.6912522 | H5: =IFERROR(_xlfn.IFS(AND(D5>100%,G5>100%),18000000,AND(D5>95%,G5>95%),10000000,AND(D5>90%,G5>95%),7000000,AND(D5>90%,G5>90%),5000000),0) -> 0 | I5: =IF(G5>=100%,"Capai","Tidak Capai Target") -> Tidak Capai Target
A6: E005 | B6: Eko Wijaya | C6: 3.6119992e+08 | D6: 0.9 | E6: =IF(D6>90%,"Rajin","Tidak Rajin") -> Tidak Rajin | F6: =SUMIF('Data Penjualan'!K:K,'Data Employee'!B6,'Data Penjualan'!H:H) -> 258361650 | G6: =F6/C6 -> 0.71528712 | H6: =IFERROR(_xlfn.IFS(AND(D6>100%,G6>100%),18000000,AND(D6>95%,G6>95%),10000000,AND(D6>90%,G6>95%),7000000,AND(D6>90%,G6>90%),5000000),0) -> 0 | I6: =IF(G6>=100%,"Capai","Tidak Capai Target") -> Tidak Capai Target
A7: E006 | B7: Fani Sari | C7: 1.0330935e+08 | D7: 0.92 | E7: =IF(D7>90%,"Rajin","Tidak Rajin") -> Rajin | F7: =SUMIF('Data Penjualan'!K:K,'Data Employee'!B7,'Data Penjualan'!H:H) -> 118154250 | G7: =F7/C7 -> 1.1436937 | H7: =IFERROR(_xlfn.IFS(AND(D7>100%,G7>100%),18000000,AND(D7>95%,G7>95%),10000000,AND(D7>90%,G7>95%),7000000,AND(D7>90%,G7>90%),5000000),0) -> 7000000 | I7: =IF(G7>=100%,"Capai","Tidak Capai Target") -> Capai
A8: E007 | B8: Gita Rahma | C8: 1.615704e+08 | D8: 0.8 | E8: =IF(D8>90%,"Rajin","Tidak Rajin") -> Tidak Rajin | F8: =SUMIF('Data Penjualan'!K:K,'Data Employee'!B8,'Data Penjualan'!H:H) -> 155930400 | G8: =F8/C8 -> 0.9650926 | H8: =IFERROR(_xlfn.IFS(AND(D8>100%,G8>100%),18000000,AND(D8>95%,G8>95%),10000000,AND(D8>90%,G8>95%),7000000,AND(D8>90%,G8>90%),5000000),0) -> 0 | I8: =IF(G8>=100%,"Capai","Tidak Capai Target") -> Tidak Capai Target
A9: E008 | B9: Hadi Nugroho | C9: 1.9059677e+08 | D9: 0.88 | E9: =IF(D9>90%,"Rajin","Tidak Rajin") -> Tidak Rajin | F9: =SUMIF('Data Penjualan'!K:K,'Data Employee'!B9,'Data Penjualan'!H:H) -> 206804000 | G9: =F9/C9 -> 1.0850341 | H9: =IFERROR(_xlfn.IFS(AND(D9>100%,G9>100%),18000000,AND(D9>95%,G9>95%),10000000,AND(D9>90%,G9>95%),7000000,AND(D9>90%,G9>90%),5000000),0) -> 0 | I9: =IF(G9>=100%,"Capai","Tidak Capai Target") -> Capai
A10: E009 | B10: Indah Putri | C10: 1.3834245e+08 | D10: 0.97 | E10: =IF(D10>90%,"Rajin","Tidak Rajin") -> Rajin | F10: =SUMIF('Data Penjualan'!K:K,'Data Employee'!B10,'Data Penjualan'!H:H) -> 112535750 | G10: =F10/C10 -> 0.81345785 | H10: =IFERROR(_xlfn.IFS(AND(D10>100%,G10>100%),18000000,AND(D10>95%,G10>95%),10000000,AND(D10>90%,G10>95%),7000000,AND(D10>90%,G10>90%),5000000),0) -> 0 | I10: =IF(G10>=100%,"Capai","Tidak Capai Target") -> Tidak Capai Target
A11: E010 | B11: Joko Susilo | C11: 1.6750616e+08 | D11: 0.89 | E11: =IF(D11>90%,"Rajin","Tidak Rajin") -> Tidak Rajin | F11: =SUMIF('Data Penjualan'!K:K,'Data Employee'!B11,'Data Penjualan'!H:H) -> 116284150 | G11: =F11/C11 -> 0.69420822 | H11: =IFERROR(_xlfn.IFS(AND(D11>100%,G11>100%),18000000,AND(D11>95%,G11>95%),10000000,AND(D11>90%,G11>95%),7000000,AND(D11>90%,G11>90%),5000000),0) -> 0 | I11: =IF(G11>=100%,"Capai","Tidak Capai Target") -> Tidak Capai Target

Sheet Data Produk
A1: ID Produk | B1: ID OUTLET | C1: Nama Barang | D1: Kategori Barang | E1: Harga per Unit
A2: ="P-0"&ROW()-1 -> P-01 | B2: O-01 | C2: BHINNEKA ATOM PRO96 95% MECHANICAL KEYBOARD MERCURY (BLACK) RED SWITCH | D2: KEYBOARD GAMING | E2: 584500
A3: ="P-0"&ROW()-1 -> P-02 | B3: O-01 | C3: BHINNEKA ATOM104 MECHANICAL KEYBOARD BLACK RED SWITCH | D3: KEYBOARD GAMING | E3: 241500
A4: ="P-0"&ROW()-1 -> P-03 | B4: O-01 | C4: BHINNEKA ATOM81 75% MECHANICAL KEYBOARD NAVY BLUE RED SWITCH | D4: KEYBOARD GAMING | E4: 230300
A5: ="P-0"&ROW()-1 -> P-04 | B5: O-01 | C5: BHINNEKA ATOM81 75% MECHANICAL KEYBOARD SKY BLUE RED SWITCH | D5: KEYBOARD GAMING | E5: 230300
A6: ="P-0"&ROW()-1 -> P-05 | B6: O-01 | C6: BHINNEKA CHIEF II HG20 GAMING HEADSET BLACK | D6: GAMING HEADSET | E6: 139300
A7: ="P-0"&ROW()-1 -> P-06 | B7: O-01 | C7: BHINNEKA CHIEF II HG20 GAMING HEADSET PINK | D7: GAMING HEADSET | E7: 139300
A8: ="P-0"&ROW()-1 -> P-07 | B8: O-01 | C8: BHINNEKA CHIEF II HG20 GAMING HEADSET WHITE | D8: GAMING HEADSET | E8: 139300
A9: ="P-0"&ROW()-1 -> P-08 | B9: O-01 | C9: BHINNEKA DURALINK KCB1201 BLACK | D9: CABLE | E9: 31500
A10: ="P-0"&ROW()-1 -> P-09 | B10: O-01 | C10: BHINNEKA DURALINK KCB1201 RED | D10: CABLE | E10: 24500
A11: ="P-"&ROW()-1 -> P-10 | B11: O-01 | C11: BHINNEKA DURALINK KCT1201 BLACK | D11: CABLE | E11: 20300
A12: ="P-"&ROW()-1 -> P-11 | B12: O-01 | C12: BHINNEKA DURALINK KCT1201 PINK | D12: CABLE | E12: 20300
A13: ="P-"&ROW()-1 -> P-12 | B13: O-01 | C13: BHINNEKA DURALINK KCT1201 WHITE | D13: CABLE | E13: 20300
A14: ="P-"&ROW()-1 -> P-13 | B14: O-01 | C14: BHINNEKA FLASH 7.1 HQ53 GAMING HEADSET BLACK | D14: GAMING HEADSET | E14: 139300
A15: ="P-"&ROW()-1 -> P-14 | B15: O-01 | C15: BHINNEKA GO TUNE WH06 WIRELESS HEADSET BEIGE | D15: WIRELESS HEADSET | E15: 181300
A16: ="P-"&ROW()-1 -> P-15 | B16: O-01 | C16: BHINNEKA GO TUNE WH06 WIRELESS HEADSET GREY | D16: WIRELESS HEADSET | E16: 181300
A17: ="P-"&ROW()-1 -> P-16 | B17: O-01 | C17: BHINNEKA GO TUNE WH06 WIRELESS HEADSET GUN (BLACK) | D17: WIRELESS HEADSET | E17: 181300
A18: ="P-"&ROW()-1 -> P-17 | B18: O-01 | C18: BHINNEKA GO VIBE WH05 WIRELESS HEADSET BLUE | D18: WIRELESS HEADSET | E18: 160300
A19: ="P-"&ROW()-1 -> P-18 | B19: O-01 | C19: BHINNEKA GO VIBE WH05 WIRELESS HEADSET PINK | D19: WIRELESS HEADSET | E19: 160300
A20: ="P-"&ROW()-1 -> P-19 | B20: O-01 | C20: BHINNEKA GO W193 OFFICE MOUSE BEIGE | D20: OFFICE MOUSE | E20: 83300
A21: ="P-"&ROW()-1 -> P-20 | B21: O-01 | C21: BHINNEKA GO W193 OFFICE MOUSE BLUE | D21: OFFICE MOUSE | E21: 83300
A22: ="P-"&ROW()-1 -> P-21 | B22: O-01 | C22: BHINNEKA GO W193 OFFICE MOUSE PINK | D22: OFFICE MOUSE | E22: 83300
... A411: ="P-"&ROW()-1 -> P-410 | B411: O-04 | C411: KC106 BHINNEKA USB CABLE TYPE C | D411: CABLE | E411: 36900
A412: ="P-"&ROW()-1 -> P-411 | B412: O-04 | C412: KC201 BHINNEKA USB CABLE TYPE C | E412: 29700
A413: ="P-"&ROW()-1 -> P-412 | B413: O-04 | C413: KDC105 BHINNEKA USB CABLE TYPE C | D413: CABLE | E413: 25200
A414: ="P-"&ROW()-1 -> P-413 | B414: O-04 | C414: KDL105 BHINNEKA USB CABLE LIGHTNING | D414: CABLE | E414: 34200
A415: ="P-"&ROW()-1 -> P-414 | B415: O-04 | C415: KL104 BHINNEKA USB CABLE LIGHTNING | D415: CABLE | E415: 36000
A416: ="P-"&ROW()-1 -> P-415 | B416: O-04 | C416: KL106 BHINNEKA USB CABLE LIGHTNING | D416: CABLE | E416: 36900
A417: ="P-"&ROW()-1 -> P-416 | B417: O-04 | C417: KL201 BHINNEKA USB CABLE LIGHTNING | D417: CABLE | E417: 29700
A418: ="P-"&ROW()-1 -> P-417 | B418: O-04 | C418: KM102 BHINNEKA USB CABLE MICRO | D418: CABLE | E418: 26100
A419: ="P-"&ROW()-1 -> P-418 | B419: O-04 | C419: KM103 BHINNEKA USB CABLE MICRO | D419: CABLE | E419: 17100
A420: ="P-"&ROW()-1 -> P-419 | B420: O-04 | C420: KM104 BHINNEKA USB CABLE MICRO | D420: CABLE | E420: 29700
A421: ="P-"&ROW()-1 -> P-420 | B421: O-04 | C421: KM106 BHINNEKA USB CABLE MICRO | D421: CABLE | E421: 34200
A422: ="P-"&ROW()-1 -> P-421 | B422: O-04 | C422: KM201 BHINNEKA USB CABLE MICRO | D422: CABLE | E422: 27000
A423: ="P-"&ROW()-1 -> P-422 | B423: O-04 | C423: WH01 BHINNEKA HEADSET WIRELESS Black | D423: WIRELESS HEADSET | E423: 348300
A424: ="P-"&ROW()-1 -> P-423 | B424: O-04 | C424: WN01 BHINNEKA EARPHONE WIRELESS | D424: EARPHONE | E424: 225000
... A451: ="P-"&ROW()-1 -> P-450 | B451: O-05 | C451: BHINNEKA Gaming Deskmat ATO MP905 KANAGAWA | D451: DESKMAT | E451: 197100
A452: ="P-"&ROW()-1 -> P-451 | B452: O-05 | C452: BHINNEKA Gaming Deskmat ATO MP905 MARBLE | E452: 170100
A453: ="P-"&ROW()-1 -> P-452 | B453: O-05 | C453: BHINNEKA Gaming Deskmat ATO MP905 PLUM | D453: DESKMAT | E453: 170100
A454: ="P-"&ROW()-1 -> P-453 | B454: O-05 | C454: BHINNEKA Gaming Earphone EG1 | D454: EARPHONE | E454: 75000
...

Sheet Data Outlet
A1: ID OUTLET | B1: Lokasi Outlet | C1: PIC
A2: O-01 | B2: AEON DELTAMAS CIKARANG | C2: E001 | D2: =VLOOKUP(C2,'Data Employee'!$A$2:$D$11,2,FALSE) -> Andi Pratama
A3: O-02 | B3: AEON MALL BSD CITY | C3: E001 | D3: =VLOOKUP(C3,'Data Employee'!$A$2:$D$11,2,FALSE) -> Andi Pratama
A4: O-03 | B4: BINTARO EXCHANGE | C4: E002 | D4: =VLOOKUP(C4,'Data Employee'!$A$2:$D$11,2,FALSE) -> Budi Santoso
A5: O-04 | B5: CENTER POINT MEDAN | C5: E003 | D5: =VLOOKUP(C5,'Data Employee'!$A$2:$D$11,2,FALSE) -> Citra Dewi
A6: O-05 | B6: CIBUBUR JUNCTION | C6: E004 | D6: =VLOOKUP(C6,'Data Employee'!$A$2:$D$11,2,FALSE) -> Dewi Lestari
A7: O-06 | B7: GRAND GALAXY PARK | C7: E004 | D7: =VLOOKUP(C7,'Data Employee'!$A$2:$D$11,2,FALSE) -> Dewi Lestari
A8: O-07 | B8: KOTA KASABLANKA | C8: E005 | D8: =VLOOKUP(C8,'Data Employee'!$A$2:$D$11,2,FALSE) -> Eko Wijaya
A9: O-08 | B9: LIPPO MALL KEMANG | C9: E006 | D9: =VLOOKUP(C9,'Data Employee'!$A$2:$D$11,2,FALSE) -> Fani Sari
A10: O-09 | B10: MALL GANDARIA CITY | C10: E007 | D10: =VLOOKUP(C10,'Data Employee'!$A$2:$D$11,2,FALSE) -> Gita Rahma
A11: O-10 | B11: MALL KELAPA GADING | C11: E008 | D11: =VLOOKUP(C11,'Data Employee'!$A$2:$D$11,2,FALSE) -> Hadi Nugroho
A12: O-11 | B12: MALL OF INDONESIA | C12: E007 | D12: =VLOOKUP(C12,'Data Employee'!$A$2:$D$11,2,FALSE) -> Gita Rahma
A13: O-12 | B13: PAKUWON | C13: E007 | D13: =VLOOKUP(C13,'Data Employee'!$A$2:$D$11,2,FALSE) -> Gita Rahma
... A17: O-16 | B17: SUMARECON MALL SERPONG | C17: E010 | D17: =VLOOKUP(C17,'Data Employee'!$A$2:$D$11,2,FALSE) -> Joko Susilo

Sheet Data Account
A1: ID Account | B1: Nama Account
A2: AC-01 | B2: PT. BHINNEKA STATIONARY
A3: AC-02 | B3: PT. BHINNEKA TOYS AND GAMING
